Workbook

Sheet Summary
A1: California ADU direct-mail targeting: top 100 ZIPs
A2: INTERIM RANKING: no county parcel data could be downloaded in this run (assessor hosts unreachable). Rank = Redfin SFR homes sold (12 mo) x tier weight, a market-size proxy, NOT a count of qualifying lots. Parcel columns read 'no data'.
A3: ZIP-level results are estimates of the share of qualifying lots, not a verified list of homes. Redfin data: 2026-05-31, 2026-02-28, 2025-11-30, 2025-08-31 windows (file updated 2026-06-02 14:33:24.470 Z).
A5: Tier | B5: Mailable ZIPs (live count) | C5: Cumulative ZIPs | D5: SFR homes sold 12 mo in tier | E5: PO-box / unique ZIPs in tier (excluded)
A6: Tier 1 (>= $700/sf) | B6: =COUNTIFS('All ZIPs'!$N$2:$N$1878,1,'All ZIPs'!$M$2:$M$1878,TRUE()) -> 389 | C6: =SUM($B$6:B6) -> 389 | D6: =SUMIFS('All ZIPs'!$K$2:$K$1878,'All ZIPs'!$N$2:$N$1878,1,'All ZIPs'!$M$2:$M$1878,TRUE()) -> 48758 | E6: =COUNTIFS('All ZIPs'!$N$2:$N$1878,1,'All ZIPs'!$M$2:$M$1878,FALSE()) -> 38
A7: Tier 2 ($600-699/sf) | B7: =COUNTIFS('All ZIPs'!$N$2:$N$1878,2,'All ZIPs'!$M$2:$M$1878,TRUE()) -> 169 | C7: =SUM($B$6:B7) -> 558 | D7: =SUMIFS('All ZIPs'!$K$2:$K$1878,'All ZIPs'!$N$2:$N$1878,2,'All ZIPs'!$M$2:$M$1878,TRUE()) -> 22518 | E7: =COUNTIFS('All ZIPs'!$N$2:$N$1878,2,'All ZIPs'!$M$2:$M$1878,FALSE()) -> 17
A8: Tier 3 ($500-599/sf) | B8: =COUNTIFS('All ZIPs'!$N$2:$N$1878,3,'All ZIPs'!$M$2:$M$1878,TRUE()) -> 178 | C8: =SUM($B$6:B8) -> 736 | D8: =SUMIFS('All ZIPs'!$K$2:$K$1878,'All ZIPs'!$N$2:$N$1878,3,'All ZIPs'!$M$2:$M$1878,TRUE()) -> 24198 | E8: =COUNTIFS('All ZIPs'!$N$2:$N$1878,3,'All ZIPs'!$M$2:$M$1878,FALSE()) -> 17
A9: Total (any tier) | B9: =SUM(B6:B8) -> 736 | D9: =SUM(D6:D8) -> 95474 | E9: =SUM(E6:E8) -> 72
A10: Snapshot sorted by the script at config.py defaults.
A11: Rank | B11: ZIP | C11: City | D11: County | E11: Focus region | F11: Neighborhoods | G11: Tier | H11: Median $/sq ft (12 mo) | I11: Median sale price (12 mo) | J11: SFR homes sold (12 mo) | K11: Est. buildable >= 750 (parcels) | L11: Score | M11: Rank basis
A12: 1 | B12: 92677 | C12: Laguna Niguel | D12: Orange | E12: Orange County | F12: El Niguel Heights; Niguel Summit | G12: Tier 1 (>= $700/sf) | H12: 811.06558 | I12: 1723455.2 | J12: 424 | K12: no data | L12: 1272 | M12: INTERIM: Redfin SFR sales (12 mo) x tier weight
A13: 2 | B13: 94550 | C13: Livermore | D13: Alameda | E13: Berkeley / Oakland / Alameda County | F13: Sandhurst; The Grove; Village II; Vinsanto II; Livermorium Plaza / Mills Square Park; Lizzie Fountain Plaza | G13: Tier 1 (>= $700/sf) | H13: 704.67241 | I13: 1341359.2 | J13: 412 | K13: no data | L13: 1236 | M13: INTERIM: Redfin SFR sales (12 mo) x tier weight
A14: 3 | B14: 95125 | C14: San Jose | D14: Santa Clara | E14: Peninsula & South Bay (Santa Clara / San Mateo) | F14: Dry Creek; Willow Glen | G14: Tier 1 (>= $700/sf) | H14: 1137.9459 | I14: 2062863.5 | J14: 381 | K14: no data | L14: 1143 | M14: INTERIM: Redfin SFR sales (12 mo) x tier weight
A15: 4 | B15: 92024 | C15: Encinitas | D15: San Diego | E15: San Diego | F15: Leucadia; Olivenhain; Downtown Encinitas; Encinitas Highlands; Encinitas Ranch; Fox Point Farms; Manzanita Cove; Old Encinitas; Pacific Serena; Val Sereno; New Encinitas; Poinsettia Heights; Quail Gardens; Rancho Encinitas; Village Park | G15: Tier 1 (>= $700/sf) | H15: 964.56064 | I15: 2278542 | J15: 369 | K15: no data | L15: 1107 | M15: INTERIM: Redfin SFR sales (12 mo) x tier weight
A16: 5 | B16: 95124 | C16: San Jose | D16: Santa Clara | E16: Peninsula & South Bay (Santa Clara / San Mateo) | F16: Willow Glen Place | G16: Tier 1 (>= $700/sf) | H16: 1220.4989 | I16: 2057880.4 | J16: 368 | K16: no data | L16: 1104 | M16: INTERIM: Redfin SFR sales (12 mo) x tier weight
A17: 6 | B17: 96161 | C17: Truckee | D17: Placer | E17: Rest of California | F17: Glenshire-Devonshire; Tahoe Donner; Armstrong; Blitz Tract; Cambridge Estates; Devonshire; Donner Crest; Donner Lake Village; Donner Pines Tract; Donner Ski Haven; Donner Tract; Donner Trail; Donner Woods; Emmons Tract; Gateway Park; Glenshire; Gray's Crossing; Juniper Creek Ranch; Juniper Heights; Juniper Hill; Klondike Flat; Lakeview; Martis Peak; Martiswood Estates; Meadow Lake Park; Old Greenwood; Olympic Heights; Plavada Woodlands; Ponderosa Fairway Estates; Ponderosa Palisades; Ponderosa Ranchos; Prosser Lake Heights; Prosser Lakeview Estates; Schaffer's Mill; Sierra Bluff; Southside Highlands; The Meadows; Weeks Tract; Gateway; Lahontan; Martis Camp; Sierra Meadows; West End Donner | G17: Tier 2 ($600-699/sf) | H17: 612.99992 | I17: 1264262.7 | J17: 533 | K17: no data | L17: 1066 | M17: INTERIM: Redfin SFR sales (12 mo) x tier weight
A18: 7 | B18: 92117 | C18: San Diego | D18: San Diego | E18: San Diego | F18: Bay Ho; Clairemont; Clairemont Mesa Gateway; Diane Village; North Mount Estates; Riviera Highlands; Triumph; Westridge; Alcott Estates; Clairemont Village; East Clairemont; Eureka Lemon; North Clairemont | G18: Tier 1 (>= $700/sf) | H18: 805.70845 | I18: 1173166.2 | J18: 349 | K18: no data | L18: 1047 | M18: INTERIM: Redfin SFR sales (12 mo) x tier weight
A19: 8 | B19: 94112 | C19: San Francisco | D19: San Francisco | E19: San Francisco | F19: Ocean View; Outer Mission; St. Mary's Park; Westwood Park; Crocker-Amazon; Excelsior; Ingleside | G19: Tier 1 (>= $700/sf) | H19: 856.09109 | I19: 1247670.1 | J19: 335 | K19: no data | L19: 1005 | M19: INTERIM: Redfin SFR sales (12 mo) x tier weight
A20: 9 | B20: 92646 | C20: Huntington Beach | D20: Orange | E20: Orange County | G20: Tier 1 (>= $700/sf) | H20: 825.07272 | I20: 1512396.4 | J20: 333 | K20: no data | L20: 999 | M20: INTERIM: Redfin SFR sales (12 mo) x tier weight
A21: 10 | B21: 94010 | C21: Burlingame | D21: San Mateo | E21: Peninsula & South Bay (Santa Clara / San Mateo) | F21: Burlingame Hills; Burlingame Village; Burlingame Town Square | G21: Tier 1 (>= $700/sf) | H21: 1516.4872 | I21: 3999650.9 | J21: 328 | K21: no data | L21: 984 | M21: INTERIM: Redfin SFR sales (12 mo) x tier weight
A22: 11 | B22: 95123 | C22: San Jose | D22: Santa Clara | E22: Peninsula & South Bay (Santa Clara / San Mateo) | F22: Parkview | G22: Tier 1 (>= $700/sf) | H22: 911.12898 | I22: 1504662.6 | J22: 326 | K22: no data | L22: 978 | M22: INTERIM: Redfin SFR sales (12 mo) x tier weight
A23: 12 | B23: 94025 | C23: Menlo Park | D23: San Mateo | E23: Peninsula & South Bay (Santa Clara / San Mateo) | F23: Stanford Hills; Stanford Weekend Acres; Hacker Square | G23: Tier 1 (>= $700/sf) | H23: 1691.4166 | I23: 3314959.5 | J23: 321 | K23: no data | L23: 963 | M23: INTERIM: Redfin SFR sales (12 mo) x tier weight
A24: 13 | B24: 90066 | C24: Los Angeles | D24: Los Angeles | E24: Los Angeles County | F24: Mar Vista; Culver Garden; Westdale; Del Rey | G24: Tier 1 (>= $700/sf) | H24: 1163.8054 | I24: 2137363.5 | J24: 315 | K24: no data | L24: 945 | M24: INTERIM: Redfin SFR sales (12 mo) x tier weight
A25: 14 | B25: 94566 | C25: Pleasanton | D25: Alameda | E25: Berkeley / Oakland / Alameda County | F25: Del Prado; Irby Ranch; Ruby Hill; Shadow Cliffs | G25: Tier 1 (>= $700/sf) | H25: 817.19279 | I25: 1860016.4 | J25: 305 | K25: no data | L25: 915 | M25: INTERIM: Redfin SFR sales (12 mo) x tier weight
A26: 15 | B26: 90275 | C26: Rancho Palos Verdes | D26: Los Angeles | E26: Los Angeles County | G26: Tier 1 (>= $700/sf) | H26: 789.09299 | I26: 1885413.9 | J26: 302 | K26: no data | L26: 906 | M26: INTERIM: Redfin SFR sales (12 mo) x tier weight
A27: 16 | B27: 94568 | C27: Dublin | D27: Alameda | E27: Berkeley / Oakland / Alameda County | G27: Tier 1 (>= $700/sf) | H27: 730.13592 | I27: 1573461.3 | J27: 297 | K27: no data | L27: 891 | M27: INTERIM: Redfin SFR sales (12 mo) x tier weight
A28: 17 | B28: 94536 | C28: Fremont | D28: Alameda | E28: Berkeley / Oakland / Alameda County | F28: Centerville District; Niles District; Niles Junction; Shinn | G28: Tier 1 (>= $700/sf) | H28: 1002.4841 | I28: 1701938.8 | J28: 294 | K28: no data | L28: 882 | M28: INTERIM: Redfin SFR sales (12 mo) x tier weight
A29: 18 | B29: 90808 | C29: Long Beach | D29: Los Angeles | E29: Los Angeles County | G29: Tier 1 (>= $700/sf) | H29: 716.19567 | I29: 1068413.8 | J29: 290 | K29: no data | L29: 870 | M29: INTERIM: Redfin SFR sales (12 mo) x tier weight
A30: 19 | B30: 92037 | C30: La Jolla | D30: San Diego | E30: San Diego | F30: La Jolla; Biology Field Station; Campus Services Complex; Earl Warren College; Eleanor Roosevelt College; John Muir College; Lower Hermosa; Miurlands West; Mount La Jolla; North Campus; Pepper Canyon; Revelle College; Ridge Walk North Living and Learning Neighborhood; Ridgegate; Science Research Park; Seventh College at the Village; Sixth College; Thurgood Marshall College; University Center; Upper Hermosa; Windansea Beach; Windemere; Beach Barber Tract; Bird Rock; Executive Square; Golden Triangle; Hidden Valley; Katzin Courtyard; La Jolla Alta; La Jolla Country Club; La Jolla Farms; La Jolla Heights; La Jolla Hermosa; La Jolla Mesa; La Jolla Shores; La Jolla Village; Matthews Quadrangle; Soledad South; The Muirlands; Village of La Jolla | G30: Tier 1 (>= $700/sf) | H30: 1361.8037 | I30: 3616364.4 | J30: 284 | K30: no data | L30: 852 | M30: INTERIM: Redfin SFR sales (12 mo) x tier weight
A31: 20 | B31: 95120 | C31: San Jose | D31: Santa Clara | E31: Peninsula & South Bay (Santa Clara / San Mateo) | F31: Almaden Valley | G31: Tier 1 (>= $700/sf) | H31: 1003.0732 | I31: 2322145.4 | J31: 282 | K31: no data | L31: 846 | M31: INTERIM: Redfin SFR sales (12 mo) x tier weight
A32: 21 | B32: 92009 | C32: Carlsbad | D32: San Diego | E32: San Diego | F32: La Costa; Bressi Ranch; La Costa Greens; La Costa Oaks; La Costa Ridge; La Costa Valley; Rancho Carrillo | G32: Tier 1 (>= $700/sf) | H32: 705.44022 | I32: 1852998.2 | J32: 281 | K32: no data | L32: 843 | M32: INTERIM: Redfin SFR sales (12 mo) x tier weight
A33: 22 | B33: 94941 | C33: Mill Valley | D33: Marin | E33: Marin | F33: Almonte | G33: Tier 1 (>= $700/sf) | H33: 1083.9878 | I33: 2277544.8 | J33: 279 | K33: no data | L33: 837 | M33: INTERIM: Redfin SFR sales (12 mo) x tier weight
A34: 23 | B34: 92129 | C34: San Diego | D34: San Diego | E34: San Diego | F34: Rancho Peñasquitos; Torrey Highlands; Greystone Torrey Highlands; Penasquitos Creek; Rhodes Crossing; Rolling Hills; Sun Ridge Vista; Terramar; Torrey Glenn; Torrey Ranch; Adobe Bluffs; Canyon Hills; Heritage Bluffs; Merge 56; Park Village; Penasquitos Village; Peñasquitos Point; Rancho Peñasquitos Town Center; Ridgewood; Sunset Hills; Torrey Del Mar; Torrey Meadows; Torrey Santa Fe; Twin Trails | G34: Tier 1 (>= $700/sf) | H34: 704.04314 | I34: 1376469.3 | J34: 277 | K34: no data | L34: 831 | M34: INTERIM: Redfin SFR sales (12 mo) x tier weight
A35: 24 | B35: 90815 | C35: Long Beach | D35: Los Angeles | E35: Los Angeles County | F35: Los Altos | G35: Tier 1 (>= $700/sf) | H35: 736.42722 | I35: 1136425.5 | J35: 275 | K35: no data | L35: 825 | M35: INTERIM: Redfin SFR sales (12 mo) x tier weight
A36: 25 | B36: 90049 | C36: Los Angeles | D36: Los Angeles | E36: Los Angeles County | F36: Brentwood; Brentwood Glen; Brentwood Heights; Brentwood Park; Brentwood Village; Westgate Heights; Republic of Artsakh Square | G36: Tier 1 (>= $700/sf) | H36: 1323.402 | I36: 4033362.6 | J36: 273 | K36: no data | L36: 819 | M36: INTERIM: Redfin SFR sales (12 mo) x tier weight
A37: 26 | B37: 94549 | C37: Lafayette | D37: Contra Costa | E37: Rest of California | F37: Burton Valley; Reliez Valley | G37: Tier 1 (>= $700/sf) | H37: 827.75787 | I37: 2055615.7 | J37: 268 | K37: no data | L37: 804 | M37: INTERIM: Redfin SFR sales (12 mo) x tier weight
A38: 27 | B38: 92651 | C38: Laguna Beach | D38: Orange | E38: Orange County | F38: Emerald Bay | G38: Tier 1 (>= $700/sf) | H38: 1545.4744 | I38: 3121949.1 | J38: 265 | K38: no data | L38: 795 | M38: INTERIM: Redfin SFR sales (12 mo) x tier weight
A39: 28 | B39: 94070 | C39: San Carlos | D39: San Mateo | E39: Peninsula & South Bay (Santa Clara / San Mateo) | F39: Devonshire | G39: Tier 1 (>= $700/sf) | H39: 1389.7012 | I39: 2696220.8 | J39: 265 | K39: no data | L39: 795 | M39: INTERIM: Redfin SFR sales (12 mo) x tier weight
A40: 29 | B40: 95127 | C40: San Jose | D40: Santa Clara | E40: Peninsula & South Bay (Santa Clara / San Mateo) | F40: Alum Rock | G40: Tier 1 (>= $700/sf) | H40: 795.73846 | I40: 1173622.6 | J40: 265 | K40: no data | L40: 795 | M40: INTERIM: Redfin SFR sales (12 mo) x tier weight
A41: 30 | B41: 94087 | C41: Sunnyvale | D41: Santa Clara | E41: Peninsula & South Bay (Santa Clara / San Mateo) | F41: Birdland | G41: Tier 1 (>= $700/sf) | H41: 1663.5655 | I41: 2974583.3 | J41: 264 | K41: no data | L41: 792 | M41: INTERIM: Redfin SFR sales (12 mo) x tier weight
...

Sheet All ZIPs
A1: Rank | B1: ZIP | C1: City | D1: County | E1: Focus region | F1: Neighborhoods | G1: Redfin metro | H1: Median sale $/sq ft (12 mo) | I1: $/sq ft basis | J1: Median sale price (12 mo) | K1: Homes sold (12 mo) | L1: Thin sample (<5 sales) | M1: Has ZIP boundary (ZCTA) | N1: Tier | O1: Tier weight | P1: Total SFR parcels | Q1: SFR lots >= 5,000 sq ft | R1: % SFR lots >= 5,000 | S1: Est. buildable >= 750 sq ft | T1: % est. buildable >= 750 | U1: Est. buildable >= 1,200 sq ft | V1: Flag: contiguous area likely < 750 | W1: Median lot size (sq ft) | X1: Parcel data | Y1: Rank score (qualifying parcels x weight) | Z1: Interim score (homes sold x weight) | AA1: Rank basis | AB1: Building footprints (all) | AC1: House-scale footprints (600-6,000 sq ft) | AD1: Footprints sourced from Microsoft | AE1: Median house-scale footprint (sq ft) | AF1: Latest-quarter $/sq ft | AG1: Latest-quarter $/sq ft YoY | AH1: County share of ZIP area | AI1: City source | AJ1: Other postal cities (>=10% of addresses) | AK1: Overture locality (largest overlap)
A2: 1 | B2: 92677 | C2: Laguna Niguel | D2: Orange | E2: Orange County | F2: El Niguel Heights; Niguel Summit | G2: Anaheim, CA | H2: 811.06558 | I2: SFR | J2: 1723455.2 | K2: 424 | M2: =TRUE() -> TRUE | N2: =IF(H2="","",IF(H2>=Assumptions!$B$5,1,IF(H2>=Assumptions!$B$6,2,IF(H2>=Assumptions!$B$7,3,"")))) -> 1 | O2: =IF(N2=1,Assumptions!$B$8,IF(N2=2,Assumptions!$B$9,IF(N2=3,Assumptions!$B$10,0))) -> 3 | P2: no data | Q2: no data | R2: no data | S2: no data | T2: no data | U2: no data | V2: no data | W2: no data | X2: no data | Y2: =IF(AND(X2="processed",ISNUMBER(S2)),S2*O2,"") | Z2: =IF(ISNUMBER(K2),K2*O2,0) -> 1272 | AA2: INTERIM: Redfin SFR sales (12 mo) x tier weight | AB2: 19157 | AC2: 17471 | AD2: 261 | AE2: 2521.2434 | AF2: 842.42056 | AG2: 0.011334465 | AH2: 1 | AI2: postal city of 100% of address points | AJ2: Laguna Niguel | AK2: Laguna Niguel
A3: 2 | B3: 94550 | C3: Livermore | D3: Alameda | E3: Berkeley / Oakland / Alameda County | F3: Sandhurst; The Grove; Village II; Vinsanto II; Livermorium Plaza / Mills Square Park; Lizzie Fountain Plaza | G3: Oakland, CA | H3: 704.67241 | I3: SFR | J3: 1341359.2 | K3: 412 | M3: =TRUE() -> TRUE | N3: =IF(H3="","",IF(H3>=Assumptions!$B$5,1,IF(H3>=Assumptions!$B$6,2,IF(H3>=Assumptions!$B$7,3,"")))) -> 1 | O3: =IF(N3=1,Assumptions!$B$8,IF(N3=2,Assumptions!$B$9,IF(N3=3,Assumptions!$B$10,0))) -> 3 | P3: no data | Q3: no data | R3: no data | S3: no data | T3: no data | U3: no data | V3: no data | W3: no data | X3: no data | Y3: =IF(AND(X3="processed",ISNUMBER(S3)),S3*O3,"") | Z3: =IF(ISNUMBER(K3),K3*O3,0) -> 1236 | AA3: INTERIM: Redfin SFR sales (12 mo) x tier weight | AB3: 21065 | AC3: 18532 | AD3: 4984 | AE3: 2510.7314 | AF3: 740.22577 | AG3: 0.019543651 | AH3: 0.67441355 | AI3: locality polygon (largest overlap) | AK3: Livermore
A4: 3 | B4: 95125 | C4: San Jose | D4: Santa Clara | E4: Peninsula & South Bay (Santa Clara / San Mateo) | F4: Dry Creek; Willow Glen | G4: San Jose, CA | H4: 1137.9459 | I4: SFR | J4: 2062863.5 | K4: 381 | M4: =TRUE() -> TRUE | N4: =IF(H4="","",IF(H4>=Assumptions!$B$5,1,IF(H4>=Assumptions!$B$6,2,IF(H4>=Assumptions!$B$7,3,"")))) -> 1 | O4: =IF(N4=1,Assumptions!$B$8,IF(N4=2,Assumptions!$B$9,IF(N4=3,Assumptions!$B$10,0))) -> 3 | P4: no data | Q4: no data | R4: no data | S4: no data | T4: no data | U4: no data | V4: no data | W4: no data | X4: no data | Y4: =IF(AND(X4="processed",ISNUMBER(S4)),S4*O4,"") | Z4: =IF(ISNUMBER(K4),K4*O4,0) -> 1143 | AA4: INTERIM: Redfin SFR sales (12 mo) x tier weight | AB4: 25731 | AC4: 17724 | AD4: 515 | AE4: 2122.4167 | AF4: 1176.0398 | AG4: -0.015815354 | AH4: 1 | AI4: postal city of 99% of address points | AJ4: San Jose | AK4: San Jose
A5: 4 | B5: 92024 | C5: Encinitas | D5: San Diego | E5: San Diego | F5: Leucadia; Olivenhain; Downtown Encinitas; Encinitas Highlands; Encinitas Ranch; Fox Point Farms; Manzanita Cove; Old Encinitas; Pacific Serena; Val Sereno; New Encinitas; Poinsettia Heights; Quail Gardens; Rancho Encinitas; Village Park | G5: San Diego, CA | H5: 964.56064 | I5: SFR | J5: 2278542 | K5: 369 | M5: =TRUE() -> TRUE | N5: =IF(H5="","",IF(H5>=Assumptions!$B$5,1,IF(H5>=Assumptions!$B$6,2,IF(H5>=Assumptions!$B$7,3,"")))) -> 1 | O5: =IF(N5=1,Assumptions!$B$8,IF(N5=2,Assumptions!$B$9,IF(N5=3,Assumptions!$B$10,0))) -> 3 | P5: no data | Q5: no data | R5: no data | S5: no data | T5: no data | U5: no data | V5: no data | W5: no data | X5: no data | Y5: =IF(AND(X5="processed",ISNUMBER(S5)),S5*O5,"") | Z5: =IF(ISNUMBER(K5),K5*O5,0) -> 1107 | AA5: INTERIM: Redfin SFR sales (12 mo) x tier weight | AB5: 21782 | AC5: 17409 | AD5: 844 | AE5: 2482.032 | AF5: 977.26857 | AG5: 0.052769642 | AH5: 0.96634422 | AI5: postal city of 99% of address points | AJ5: Encinitas | AK5: Encinitas
A6: 5 | B6: 95124 | C6: San Jose | D6: Santa Clara | E6: Peninsula & South Bay (Santa Clara / San Mateo) | F6: Willow Glen Place | G6: San Jose, CA | H6: 1220.4989 | I6: SFR | J6: 2057880.4 | K6: 368 | M6: =TRUE() -> TRUE | N6: =IF(H6="","",IF(H6>=Assumptions!$B$5,1,IF(H6>=Assumptions!$B$6,2,IF(H6>=Assumptions!$B$7,3,"")))) -> 1 | O6: =IF(N6=1,Assumptions!$B$8,IF(N6=2,Assumptions!$B$9,IF(N6=3,Assumptions!$B$10,0))) -> 3 | P6: no data | Q6: no data | R6: no data | S6: no data | T6: no data | U6: no data | V6: no data | W6: no data | X6: no data | Y6: =IF(AND(X6="processed",ISNUMBER(S6)),S6*O6,"") | Z6: =IF(ISNUMBER(K6),K6*O6,0) -> 1104 | AA6: INTERIM: Redfin SFR sales (12 mo) x tier weight | AB6: 20690 | AC6: 15442 | AD6: 190 | AE6: 2457.561 | AF6: 1261.6487 | AG6: -0.0070049688 | AH6: 1 | AI6: postal city of 99% of address points | AJ6: San Jose | AK6: San Jose
A7: 6 | B7: 96161 | C7: Truckee | D7: Placer | E7: Rest of California | F7: Glenshire-Devonshire; Tahoe Donner; Armstrong; Blitz Tract; Cambridge Estates; Devonshire; Donner Crest; Donner Lake Village; Donner Pines Tract; Donner Ski Haven; Donner Tract; Donner Trail; Donner Woods; Emmons Tract; Gateway Park; Glenshire; Gray's Crossing; Juniper Creek Ranch; Juniper Heights; Juniper Hill; Klondike Flat; Lakeview; Martis Peak; Martiswood Estates; Meadow Lake Park; Old Greenwood; Olympic Heights; Plavada Woodlands; Ponderosa Fairway Estates; Ponderosa Palisades; Ponderosa Ranchos; Prosser Lake Heights; Prosser Lakeview Estates; Schaffer's Mill; Sierra Bluff; Southside Highlands; The Meadows; Weeks Tract; Gateway; Lahontan; Martis Camp; Sierra Meadows; West End Donner | G7: Sacramento, CA | H7: 612.99992 | I7: SFR | J7: 1264262.7 | K7: 533 | M7: =TRUE() -> TRUE | N7: =IF(H7="","",IF(H7>=Assumptions!$B$5,1,IF(H7>=Assumptions!$B$6,2,IF(H7>=Assumptions!$B$7,3,"")))) -> 2 | O7: =IF(N7=1,Assumptions!$B$8,IF(N7=2,Assumptions!$B$9,IF(N7=3,Assumptions!$B$10,0))) -> 2 | P7: no data | Q7: no data | R7: no data | S7: no data | T7: no data | U7: no data | V7: no data | W7: no data | X7: no data | Y7: =IF(AND(X7="processed",ISNUMBER(S7)),S7*O7,"") | Z7: =IF(ISNUMBER(K7),K7*O7,0) -> 1066 | AA7: INTERIM: Redfin SFR sales (12 mo) x tier weight | AB7: 16846 | AC7: 15188 | AD7: 11181 | AE7: 1971.8755 | AF7: 649.99596 | AG7: 0.012026708 | AH7: 0.56042357 | AI7: postal city of 100% of address points | AJ7: Truckee | AK7: Truckee
A8: 7 | B8: 92117 | C8: San Diego | D8: San Diego | E8: San Diego | F8: Bay Ho; Clairemont; Clairemont Mesa Gateway; Diane Village; North Mount Estates; Riviera Highlands; Triumph; Westridge; Alcott Estates; Clairemont Village; East Clairemont; Eureka Lemon; North Clairemont | G8: San Diego, CA | H8: 805.70845 | I8: SFR | J8: 1173166.2 | K8: 349 | M8: =TRUE() -> TRUE | N8: =IF(H8="","",IF(H8>=Assumptions!$B$5,1,IF(H8>=Assumptions!$B$6,2,IF(H8>=Assumptions!$B$7,3,"")))) -> 1 | O8: =IF(N8=1,Assumptions!$B$8,IF(N8=2,Assumptions!$B$9,IF(N8=3,Assumptions!$B$10,0))) -> 3 | P8: no data | Q8: no data | R8: no data | S8: no data | T8: no data | U8: no data | V8: no data | W8: no data | X8: no data | Y8: =IF(AND(X8="processed",ISNUMBER(S8)),S8*O8,"") | Z8: =IF(ISNUMBER(K8),K8*O8,0) -> 1047 | AA8: INTERIM: Redfin SFR sales (12 mo) x tier weight | AB8: 18445 | AC8: 15595 | AD8: 544 | AE8: 2245.3982 | AF8: 827.52613 | AG8: 0.047134748 | AH8: 1 | AI8: postal city of 100% of address points | AJ8: San Diego | AK8: San Diego
A9: 8 | B9: 94112 | C9: San Francisco | D9: San Francisco | E9: San Francisco | F9: Ocean View; Outer Mission; St. Mary's Park; Westwood Park; Crocker-Amazon; Excelsior; Ingleside | G9: San Francisco, CA | H9: 856.09109 | I9: SFR | J9: 1247670.1 | K9: 335 | M9: =TRUE() -> TRUE | N9: =IF(H9="","",IF(H9>=Assumptions!$B$5,1,IF(H9>=Assumptions!$B$6,2,IF(H9>=Assumptions!$B$7,3,"")))) -> 1 | O9: =IF(N9=1,Assumptions!$B$8,IF(N9=2,Assumptions!$B$9,IF(N9=3,Assumptions!$B$10,0))) -> 3 | P9: no data | Q9: no data | R9: no data | S9: no data | T9: no data | U9: no data | V9: no data | W9: no data | X9: no data | Y9: =IF(AND(X9="processed",ISNUMBER(S9)),S9*O9,"") | Z9: =IF(ISNUMBER(K9),K9*O9,0) -> 1005 | AA9: INTERIM: Redfin SFR sales (12 mo) x tier weight | AB9: 19050 | AC9: 18175 | AD9: 147 | AE9: 1289.9436 | AF9: 919.41392 | AG9: 0.15367727 | AH9: 0.99863204 | AI9: postal city of 100% of address points | AJ9: San Francisco | AK9: Daly City
A10: 9 | B10: 92646 | C10: Huntington Beach | D10: Orange | E10: Orange County | G10: Anaheim, CA | H10: 825.07272 | I10: SFR | J10: 1512396.4 | K10: 333 | M10: =TRUE() -> TRUE | N10: =IF(H10="","",IF(H10>=Assumptions!$B$5,1,IF(H10>=Assumptions!$B$6,2,IF(H10>=Assumptions!$B$7,3,"")))) -> 1 | O10: =IF(N10=1,Assumptions!$B$8,IF(N10=2,Assumptions!$B$9,IF(N10=3,Assumptions!$B$10,0))) -> 3 | P10: no data | Q10: no data | R10: no data | S10: no data | T10: no data | U10: no data | V10: no data | W10: no data | X10: no data | Y10: =IF(AND(X10="processed",ISNUMBER(S10)),S10*O10,"") | Z10: =IF(ISNUMBER(K10),K10*O10,0) -> 999 | AA10: INTERIM: Redfin SFR sales (12 mo) x tier weight | AB10: 18051 | AC10: 16987 | AD10: 534 | AE10: 2346.4419 | AF10: 839.73129 | AG10: 0.035250809 | AH10: 0.94444728 | AI10: postal city of 100% of address points | AJ10: Huntington Beach | AK10: Huntington Beach
A11: 10 | B11: 94010 | C11: Burlingame | D11: San Mateo | E11: Peninsula & South Bay (Santa Clara / San Mateo) | F11: Burlingame Hills; Burlingame Village; Burlingame Town Square | G11: San Francisco, CA | H11: 1516.4872 | I11: SFR | J11: 3999650.9 | K11: 328 | M11: =TRUE() -> TRUE | N11: =IF(H11="","",IF(H11>=Assumptions!$B$5,1,IF(H11>=Assumptions!$B$6,2,IF(H11>=Assumptions!$B$7,3,"")))) -> 1 | O11: =IF(N11=1,Assumptions!$B$8,IF(N11=2,Assumptions!$B$9,IF(N11=3,Assumptions!$B$10,0))) -> 3 | P11: no data | Q11: no data | R11: no data | S11: no data | T11: no data | U11: no data | V11: no data | W11: no data | X11: no data | Y11: =IF(AND(X11="processed",ISNUMBER(S11)),S11*O11,"") | Z11: =IF(ISNUMBER(K11),K11*O11,0) -> 984 | AA11: INTERIM: Redfin SFR sales (12 mo) x tier weight | AB11: 15853 | AC11: 12741 | AD11: 617 | AE11: 2403.5564 | AF11: 1573.5641 | AG11: 0.068606402 | AH11: 0.9782138 | AI11: postal city of 71% of address points | AJ11: Burlingame; Hillsborough | AK11: Hillsborough
A12: 11 | B12: 95123 | C12: San Jose | D12: Santa Clara | E12: Peninsula & South Bay (Santa Clara / San Mateo) | F12: Parkview | G12: San Jose, CA | H12: 911.12898 | I12: SFR | J12: 1504662.6 | K12: 326 | M12: =TRUE() -> TRUE | N12: =IF(H12="","",IF(H12>=Assumptions!$B$5,1,IF(H12>=Assumptions!$B$6,2,IF(H12>=Assumptions!$B$7,3,"")))) -> 1 | O12: =IF(N12=1,Assumptions!$B$8,IF(N12=2,Assumptions!$B$9,IF(N12=3,Assumptions!$B$10,0))) -> 3 | P12: no data | Q12: no data | R12: no data | S12: no data | T12: no data | U12: no data | V12: no data | W12: no data | X12: no data | Y12: =IF(AND(X12="processed",ISNUMBER(S12)),S12*O12,"") | Z12: =IF(ISNUMBER(K12),K12*O12,0) -> 978 | AA12: INTERIM: Redfin SFR sales (12 mo) x tier weight | AB12: 20834 | AC12: 16054 | AD12: 196 | AE12: 2331.7593 | AF12: 920.91008 | AG12: -0.031627636 | AH12: 1 | AI12: postal city of 100% of address points | AJ12: San Jose | AK12: San Jose
A13: 12 | B13: 94025 | C13: Menlo Park | D13: San Mateo | E13: Peninsula & South Bay (Santa Clara / San Mateo) | F13: Stanford Hills; Stanford Weekend Acres; Hacker Square | G13: San Francisco, CA | H13: 1691.4166 | I13: SFR | J13: 3314959.5 | K13: 321 | M13: =TRUE() -> TRUE | N13: =IF(H13="","",IF(H13>=Assumptions!$B$5,1,IF(H13>=Assumptions!$B$6,2,IF(H13>=Assumptions!$B$7,3,"")))) -> 1 | O13: =IF(N13=1,Assumptions!$B$8,IF(N13=2,Assumptions!$B$9,IF(N13=3,Assumptions!$B$10,0))) -> 3 | P13: no data | Q13: no data | R13: no data | S13: no data | T13: no data | U13: no data | V13: no data | W13: no data | X13: no data | Y13: =IF(AND(X13="processed",ISNUMBER(S13)),S13*O13,"") | Z13: =IF(ISNUMBER(K13),K13*O13,0) -> 963 | AA13: INTERIM: Redfin SFR sales (12 mo) x tier weight | AB13: 16385 | AC13: 13018 | AD13: 135 | AE13: 2194.3567 | AF13: 1753.3715 | AG13: 0.06321944 | AH13: 0.97136118 | AI13: postal city of 98% of address points | AJ13: Menlo Park | AK13: Menlo Park
A14: 13 | B14: 90066 | C14: Los Angeles | D14: Los Angeles | E14: Los Angeles County | F14: Mar Vista; Culver Garden; Westdale; Del Rey | G14: Los Angeles, CA | H14: 1163.8054 | I14: SFR | J14: 2137363.5 | K14: 315 | M14: =TRUE() -> TRUE | N14: =IF(H14="","",IF(H14>=Assumptions!$B$5,1,IF(H14>=Assumptions!$B$6,2,IF(H14>=Assumptions!$B$7,3,"")))) -> 1 | O14: =IF(N14=1,Assumptions!$B$8,IF(N14=2,Assumptions!$B$9,IF(N14=3,Assumptions!$B$10,0))) -> 3 | P14: no data | Q14: no data | R14: no data | S14: no data | T14: no data | U14: no data | V14: no data | W14: no data | X14: no data | Y14: =IF(AND(X14="processed",ISNUMBER(S14)),S14*O14,"") | Z14: =IF(ISNUMBER(K14),K14*O14,0) -> 945 | AA14: INTERIM: Redfin SFR sales (12 mo) x tier weight | AB14: 20229 | AC14: 13736 | AD14: 93 | AE14: 1785.4412 | AF14: 1157.8604 | AG14: 0.012843134 | AH14: 1 | AI14: postal city of 100% of address points | AJ14: Los Angeles | AK14: Los Angeles
A15: 14 | B15: 94566 | C15: Pleasanton | D15: Alameda | E15: Berkeley / Oakland / Alameda County | F15: Del Prado; Irby Ranch; Ruby Hill; Shadow Cliffs | G15: Oakland, CA | H15: 817.19279 | I15: SFR | J15: 1860016.4 | K15: 305 | M15: =TRUE() -> TRUE | N15: =IF(H15="","",IF(H15>=Assumptions!$B$5,1,IF(H15>=Assumptions!$B$6,2,IF(H15>=Assumptions!$B$7,3,"")))) -> 1 | O15: =IF(N15=1,Assumptions!$B$8,IF(N15=2,Assumptions!$B$9,IF(N15=3,Assumptions!$B$10,0))) -> 3 | P15: no data | Q15: no data | R15: no data | S15: no data | T15: no data | U15: no data | V15: no data | W15: no data | X15: no data | Y15: =IF(AND(X15="processed",ISNUMBER(S15)),S15*O15,"") | Z15: =IF(ISNUMBER(K15),K15*O15,0) -> 915 | AA15: INTERIM: Redfin SFR sales (12 mo) x tier weight | AB15: 14276 | AC15: 12880 | AD15: 1613 | AE15: 2527.3198 | AF15: 864.45354 | AG15: -0.035685599 | AH15: 1 | AI15: locality polygon (largest overlap) | AK15: Pleasanton
A16: 15 | B16: 90275 | C16: Rancho Palos Verdes | D16: Los Angeles | E16: Los Angeles County | G16: Los Angeles, CA | H16: 789.09299 | I16: SFR | J16: 1885413.9 | K16: 302 | M16: =TRUE() -> TRUE | N16: =IF(H16="","",IF(H16>=Assumptions!$B$5,1,IF(H16>=Assumptions!$B$6,2,IF(H16>=Assumptions!$B$7,3,"")))) -> 1 | O16: =IF(N16=1,Assumptions!$B$8,IF(N16=2,Assumptions!$B$9,IF(N16=3,Assumptions!$B$10,0))) -> 3 | P16: no data | Q16: no data | R16: no data | S16: no data | T16: no data | U16: no data | V16: no data | W16: no data | X16: no data | Y16: =IF(AND(X16="processed",ISNUMBER(S16)),S16*O16,"") | Z16: =IF(ISNUMBER(K16),K16*O16,0) -> 906 | AA16: INTERIM: Redfin SFR sales (12 mo) x tier weight | AB16: 14943 | AC16: 13618 | AD16: 192 | AE16: 2939.3169 | AF16: 767.45465 | AG16: -0.054227908 | AH16: 0.80379325 | AI16: postal city of 100% of address points | AJ16: Rancho Palos Verdes | AK16: Rancho Palos Verdes
A17: 16 | B17: 94568 | C17: Dublin | D17: Alameda | E17: Berkeley / Oakland / Alameda County | G17: Oakland, CA | H17: 730.13592 | I17: SFR | J17: 1573461.3 | K17: 297 | M17: =TRUE() -> TRUE | N17: =IF(H17="","",IF(H17>=Assumptions!$B$5,1,IF(H17>=Assumptions!$B$6,2,IF(H17>=Assumptions!$B$7,3,"")))) -> 1 | O17: =IF(N17=1,Assumptions!$B$8,IF(N17=2,Assumptions!$B$9,IF(N17=3,Assumptions!$B$10,0))) -> 3 | P17: no data | Q17: no data | R17: no data | S17: no data | T17: no data | U17: no data | V17: no data | W17: no data | X17: no data | Y17: =IF(AND(X17="processed",ISNUMBER(S17)),S17*O17,"") | Z17: =IF(ISNUMBER(K17),K17*O17,0) -> 891 | AA17: INTERIM: Redfin SFR sales (12 mo) x tier weight | AB17: 14324 | AC17: 13010 | AD17: 950 | AE17: 2109.5432 | AF17: 691.59316 | AG17: -0.095818594 | AH17: 0.99834932 | AI17: locality polygon (largest overlap) | AK17: Dublin
A18: 17 | B18: 94536 | C18: Fremont | D18: Alameda | E18: Berkeley / Oakland / Alameda County | F18: Centerville District; Niles District; Niles Junction; Shinn | G18: Oakland, CA | H18: 1002.4841 | I18: SFR | J18: 1701938.8 | K18: 294 | M18: =TRUE() -> TRUE | N18: =IF(H18="","",IF(H18>=Assumptions!$B$5,1,IF(H18>=Assumptions!$B$6,2,IF(H18>=Assumptions!$B$7,3,"")))) -> 1 | O18: =IF(N18=1,Assumptions!$B$8,IF(N18=2,Assumptions!$B$9,IF(N18=3,Assumptions!$B$10,0))) -> 3 | P18: no data | Q18: no data | R18: no data | S18: no data | T18: no data | U18: no data | V18: no data | W18: no data | X18: no data | Y18: =IF(AND(X18="processed",ISNUMBER(S18)),S18*O18,"") | Z18: =IF(ISNUMBER(K18),K18*O18,0) -> 882 | AA18: INTERIM: Redfin SFR sales (12 mo) x tier weight | AB18: 20813 | AC18: 17549 | AD18: 97 | AE18: 2348.4919 | AF18: 991.73554 | AG18: -0.053512397 | AH18: 1 | AI18: locality polygon (largest overlap) | AK18: Fremont
A19: 18 | B19: 90808 | C19: Long Beach | D19: Los Angeles | E19: Los Angeles County | G19: Los Angeles, CA | H19: 716.19567 | I19: SFR | J19: 1068413.8 | K19: 290 | M19: =TRUE() -> TRUE | N19: =IF(H19="","",IF(H19>=Assumptions!$B$5,1,IF(H19>=Assumptions!$B$6,2,IF(H19>=Assumptions!$B$7,3,"")))) -> 1 | O19: =IF(N19=1,Assumptions!$B$8,IF(N19=2,Assumptions!$B$9,IF(N19=3,Assumptions!$B$10,0))) -> 3 | P19: no data | Q19: no data | R19: no data | S19: no data | T19: no data | U19: no data | V19: no data | W19: no data | X19: no data | Y19: =IF(AND(X19="processed",ISNUMBER(S19)),S19*O19,"") | Z19: =IF(ISNUMBER(K19),K19*O19,0) -> 870 | AA19: INTERIM: Redfin SFR sales (12 mo) x tier weight | AB19: 21868 | AC19: 15489 | AD19: 173 | AE19: 1964.3456 | AF19: 709.59159 | AG19: -0.086511294 | AH19: 0.99960364 | AI19: postal city of 100% of address points | AJ19: Long Beach | AK19: Long Beach
A20: 19 | B20: 92037 | C20: La Jolla | D20: San Diego | E20: San Diego | F20: La Jolla; Biology Field Station; Campus Services Complex; Earl Warren College; Eleanor Roosevelt College; John Muir College; Lower Hermosa; Miurlands West; Mount La Jolla; North Campus; Pepper Canyon; Revelle College; Ridge Walk North Living and Learning Neighborhood; Ridgegate; Science Research Park; Seventh College at the Village; Sixth College; Thurgood Marshall College; University Center; Upper Hermosa; Windansea Beach; Windemere; Beach Barber Tract; Bird Rock; Executive Square; Golden Triangle; Hidden Valley; Katzin Courtyard; La Jolla Alta; La Jolla Country Club; La Jolla Farms; La Jolla Heights; La Jolla Hermosa; La Jolla Mesa; La Jolla Shores; La Jolla Village; Matthews Quadrangle; Soledad South; The Muirlands; Village of La Jolla | G20: San Diego, CA | H20: 1361.8037 | I20: SFR | J20: 3616364.4 | K20: 284 | M20: =TRUE() -> TRUE | N20: =IF(H20="","",IF(H20>=Assumptions!$B$5,1,IF(H20>=Assumptions!$B$6,2,IF(H20>=Assumptions!$B$7,3,"")))) -> 1 | O20: =IF(N20=1,Assumptions!$B$8,IF(N20=2,Assumptions!$B$9,IF(N20=3,Assumptions!$B$10,0))) -> 3 | P20: no data | Q20: no data | R20: no data | S20: no data | T20: no data | U20: no data | V20: no data | W20: no data | X20: no data | Y20: =IF(AND(X20="processed",ISNUMBER(S20)),S20*O20,"") | Z20: =IF(ISNUMBER(K20),K20*O20,0) -> 852 | AA20: INTERIM: Redfin SFR sales (12 mo) x tier weight | AB20: 14975 | AC20: 11792 | AD20: 388 | AE20: 2963.929 | AF20: 1372.7698 | AG20: 0.065571199 | AH20: 0.9022674 | AI20: postal city of 100% of address points | AJ20: La Jolla | AK20: San Diego
A21: 20 | B21: 95120 | C21: San Jose | D21: Santa Clara | E21: Peninsula & South Bay (Santa Clara / San Mateo) | F21: Almaden Valley | G21: San Jose, CA | H21: 1003.0732 | I21: SFR | J21: 2322145.4 | K21: 282 | M21: =TRUE() -> TRUE | N21: =IF(H21="","",IF(H21>=Assumptions!$B$5,1,IF(H21>=Assumptions!$B$6,2,IF(H21>=Assumptions!$B$7,3,"")))) -> 1 | O21: =IF(N21=1,Assumptions!$B$8,IF(N21=2,Assumptions!$B$9,IF(N21=3,Assumptions!$B$10,0))) -> 3 | P21: no data | Q21: no data | R21: no data | S21: no data | T21: no data | U21: no data | V21: no data | W21: no data | X21: no data | Y21: =IF(AND(X21="processed",ISNUMBER(S21)),S21*O21,"") | Z21: =IF(ISNUMBER(K21),K21*O21,0) -> 846 | AA21: INTERIM: Redfin SFR sales (12 mo) x tier weight | AB21: 17646 | AC21: 12737 | AD21: 638 | AE21: 2787.3027 | AF21: 1039.268 | AG21: -0.016310202 | AH21: 1 | AI21: postal city of 100% of address points | AJ21: San Jose | AK21: San Jose
A22: 21 | B22: 92009 | C22: Carlsbad | D22: San Diego | E22: San Diego | F22: La Costa; Bressi Ranch; La Costa Greens; La Costa Oaks; La Costa Ridge; La Costa Valley; Rancho Carrillo | G22: San Diego, CA | H22: 705.44022 | I22: SFR | J22: 1852998.2 | K22: 281 | M22: =TRUE() -> TRUE | N22: =IF(H22="","",IF(H22>=Assumptions!$B$5,1,IF(H22>=Assumptions!$B$6,2,IF(H22>=Assumptions!$B$7,3,"")))) -> 1 | O22: =IF(N22=1,Assumptions!$B$8,IF(N22=2,Assumptions!$B$9,IF(N22=3,Assumptions!$B$10,0))) -> 3 | P22: no data | Q22: no data | R22: no data | S22: no data | T22: no data | U22: no data | V22: no data | W22: no data | X22: no data | Y22: =IF(AND(X22="processed",ISNUMBER(S22)),S22*O22,"") | Z22: =IF(ISNUMBER(K22),K22*O22,0) -> 843 | AA22: INTERIM: Redfin SFR sales (12 mo) x tier weight | AB22: 13786 | AC22: 12308 | AD22: 155 | AE22: 2809.7068 | AF22: 704.18698 | AG22: -0.037496793 | AH22: 0.98988361 | AI22: postal city of 100% of address points | AJ22: Carlsbad | AK22: Carlsbad
A23: 22 | B23: 94941 | C23: Mill Valley | D23: Marin | E23: Marin | F23: Almonte | G23: San Rafael, CA | H23: 1083.9878 | I23: SFR | J23: 2277544.8 | K23: 279 | M23: =TRUE() -> TRUE | N23: =IF(H23="","",IF(H23>=Assumptions!$B$5,1,IF(H23>=Assumptions!$B$6,2,IF(H23>=Assumptions!$B$7,3,"")))) -> 1 | O23: =IF(N23=1,Assumptions!$B$8,IF(N23=2,Assumptions!$B$9,IF(N23=3,Assumptions!$B$10,0))) -> 3 | P23: no data | Q23: no data | R23: no data | S23: no data | T23: no data | U23: no data | V23: no data | W23: no data | X23: no data | Y23: =IF(AND(X23="processed",ISNUMBER(S23)),S23*O23,"") | Z23: =IF(ISNUMBER(K23),K23*O23,0) -> 837 | AA23: INTERIM: Redfin SFR sales (12 mo) x tier weight | AB23: 14418 | AC23: 11097 | AD23: 329 | AE23: 1839.2679 | AF23: 1123.1884 | AG23: 0.04435088 | AH23: 0.96647119 | AI23: postal city of 100% of address points | AJ23: Mill Valley | AK23: Mill Valley
A24: 23 | B24: 92129 | C24: San Diego | D24: San Diego | E24: San Diego | F24: Rancho Peñasquitos; Torrey Highlands; Greystone Torrey Highlands; Penasquitos Creek; Rhodes Crossing; Rolling Hills; Sun Ridge Vista; Terramar; Torrey Glenn; Torrey Ranch; Adobe Bluffs; Canyon Hills; Heritage Bluffs; Merge 56; Park Village; Penasquitos Village; Peñasquitos Point; Rancho Peñasquitos Town Center; Ridgewood; Sunset Hills; Torrey Del Mar; Torrey Meadows; Torrey Santa Fe; Twin Trails | G24: San Diego, CA | H24: 704.04314 | I24: SFR | J24: 1376469.3 | K24: 277 | M24: =TRUE() -> TRUE | N24: =IF(H24="","",IF(H24>=Assumptions!$B$5,1,IF(H24>=Assumptions!$B$6,2,IF(H24>=Assumptions!$B$7,3,"")))) -> 1 | O24: =IF(N24=1,Assumptions!$B$8,IF(N24=2,Assumptions!$B$9,IF(N24=3,Assumptions!$B$10,0))) -> 3 | P24: no data | Q24: no data | R24: no data | S24: no data | T24: no data | U24: no data | V24: no data | W24: no data | X24: no data | Y24: =IF(AND(X24="processed",ISNUMBER(S24)),S24*O24,"") | Z24: =IF(ISNUMBER(K24),K24*O24,0) -> 831 | AA24: INTERIM: Redfin SFR sales (12 mo) x tier weight | AB24: 14991 | AC24: 14004 | AD24: 2541 | AE24: 2353.5459 | AF24: 740.04671 | AG24: -0.011827258 | AH24: 1 | AI24: postal city of 100% of address points | AJ24: San Diego | AK24: San Diego
A25: 24 | B25: 90815 | C25: Long Beach | D25: Los Angeles | E25: Los Angeles County | F25: Los Altos | G25: Los Angeles, CA | H25: 736.42722 | I25: SFR | J25: 1136425.5 | K25: 275 | M25: =TRUE() -> TRUE | N25: =IF(H25="","",IF(H25>=Assumptions!$B$5,1,IF(H25>=Assumptions!$B$6,2,IF(H25>=Assumptions!$B$7,3,"")))) -> 1 | O25: =IF(N25=1,Assumptions!$B$8,IF(N25=2,Assumptions!$B$9,IF(N25=3,Assumptions!$B$10,0))) -> 3 | P25: no data | Q25: no data | R25: no data | S25: no data | T25: no data | U25: no data | V25: no data | W25: no data | X25: no data | Y25: =IF(AND(X25="processed",ISNUMBER(S25)),S25*O25,"") | Z25: =IF(ISNUMBER(K25),K25*O25,0) -> 825 | AA25: INTERIM: Redfin SFR sales (12 mo) x tier weight | AB25: 18313 | AC25: 13177 | AD25: 127 | AE25: 2100.2444 | AF25: 767.89838 | AG25: 0.12549254 | AH25: 0.99850212 | AI25: postal city of 100% of address points | AJ25: Long Beach | AK25: Long Beach
A26: 25 | B26: 90049 | C26: Los Angeles | D26: Los Angeles | E26: Los Angeles County | F26: Brentwood; Brentwood Glen; Brentwood Heights; Brentwood Park; Brentwood Village; Westgate Heights; Republic of Artsakh Square | G26: Los Angeles, CA | H26: 1323.402 | I26: SFR | J26: 4033362.6 | K26: 273 | M26: =TRUE() -> TRUE | N26: =IF(H26="","",IF(H26>=Assumptions!$B$5,1,IF(H26>=Assumptions!$B$6,2,IF(H26>=Assumptions!$B$7,3,"")))) -> 1 | O26: =IF(N26=1,Assumptions!$B$8,IF(N26=2,Assumptions!$B$9,IF(N26=3,Assumptions!$B$10,0))) -> 3 | P26: no data | Q26: no data | R26: no data | S26: no data | T26: no data | U26: no data | V26: no data | W26: no data | X26: no data | Y26: =IF(AND(X26="processed",ISNUMBER(S26)),S26*O26,"") | Z26: =IF(ISNUMBER(K26),K26*O26,0) -> 819 | AA26: INTERIM: Redfin SFR sales (12 mo) x tier weight | AB26: 11865 | AC26: 8963 | AD26: 185 | AE26: 3101.5984 | AF26: 1284.9162 | AG26: -0.03792536 | AH26: 1 | AI26: postal city of 100% of address points | AJ26: Los Angeles | AK26: Los Angeles
A27: 26 | B27: 94549 | C27: Lafayette | D27: Contra Costa | E27: Rest of California | F27: Burton Valley; Reliez Valley | G27: Oakland, CA | H27: 827.75787 | I27: SFR | J27: 2055615.7 | K27: 268 | M27: =TRUE() -> TRUE | N27: =IF(H27="","",IF(H27>=Assumptions!$B$5,1,IF(H27>=Assumptions!$B$6,2,IF(H27>=Assumptions!$B$7,3,"")))) -> 1 | O27: =IF(N27=1,Assumptions!$B$8,IF(N27=2,Assumptions!$B$9,IF(N27=3,Assumptions!$B$10,0))) -> 3 | P27: no data | Q27: no data | R27: no data | S27: no data | T27: no data | U27: no data | V27: no data | W27: no data | X27: no data | Y27: =IF(AND(X27="processed",ISNUMBER(S27)),S27*O27,"") | Z27: =IF(ISNUMBER(K27),K27*O27,0) -> 804 | AA27: INTERIM: Redfin SFR sales (12 mo) x tier weight | AB27: 10986 | AC27: 9858 | AD27: 9532 | AE27: 3016.2686 | AF27: 846.5198 | AG27: -0.058195321 | AH27: 1 | AI27: postal city of 100% of address points | AJ27: Lafayette | AK27: Lafayette
A28: 27 | B28: 92651 | C28: Laguna Beach | D28: Orange | E28: Orange County | F28: Emerald Bay | G28: Anaheim, CA | H28: 1545.4744 | I28: SFR | J28: 3121949.1 | K28: 265 | M28: =TRUE() -> TRUE | N28: =IF(H28="","",IF(H28>=Assumptions!$B$5,1,IF(H28>=Assumptions!$B$6,2,IF(H28>=Assumptions!$B$7,3,"")))) -> 1 | O28: =IF(N28=1,Assumptions!$B$8,IF(N28=2,Assumptions!$B$9,IF(N28=3,Assumptions!$B$10,0))) -> 3 | P28: no data | Q28: no data | R28: no data | S28: no data | T28: no data | U28: no data | V28: no data | W28: no data | X28: no data | Y28: =IF(AND(X28="processed",ISNUMBER(S28)),S28*O28,"") | Z28: =IF(ISNUMBER(K28),K28*O28,0) -> 795 | AA28: INTERIM: Redfin SFR sales (12 mo) x tier weight | AB28: 12290 | AC28: 10871 | AD28: 222 | AE28: 2074.5979 | AF28: 1541.6263 | AG28: -0.056773413 | AH28: 0.87800533 | AI28: postal city of 99% of address points | AJ28: Laguna Beach | AK28: Laguna Beach
A29: 28 | B29: 94070 | C29: San Carlos | D29: San Mateo | E29: Peninsula & South Bay (Santa Clara / San Mateo) | F29: Devonshire | G29: San Francisco, CA | H29: 1389.7012 | I29: SFR | J29: 2696220.8 | K29: 265 | M29: =TRUE() -> TRUE | N29: =IF(H29="","",IF(H29>=Assumptions!$B$5,1,IF(H29>=Assumptions!$B$6,2,IF(H29>=Assumptions!$B$7,3,"")))) -> 1 | O29: =IF(N29=1,Assumptions!$B$8,IF(N29=2,Assumptions!$B$9,IF(N29=3,Assumptions!$B$10,0))) -> 3 | P29: no data | Q29: no data | R29: no data | S29: no data | T29: no data | U29: no data | V29: no data | W29: no data | X29: no data | Y29: =IF(AND(X29="processed",ISNUMBER(S29)),S29*O29,"") | Z29: =IF(ISNUMBER(K29),K29*O29,0) -> 795 | AA29: INTERIM: Redfin SFR sales (12 mo) x tier weight | AB29: 11614 | AC29: 9901 | AD29: 134 | AE29: 2264.7549 | AF29: 1447.9167 | AG29: -0.064509352 | AH29: 0.99905451 | AI29: postal city of 99% of address points | AJ29: San Carlos | AK29: San Carlos
A30: 29 | B30: 95127 | C30: San Jose | D30: Santa Clara | E30: Peninsula & South Bay (Santa Clara / San Mateo) | F30: Alum Rock | G30: San Jose, CA | H30: 795.73846 | I30: SFR | J30: 1173622.6 | K30: 265 | M30: =TRUE() -> TRUE | N30: =IF(H30="","",IF(H30>=Assumptions!$B$5,1,IF(H30>=Assumptions!$B$6,2,IF(H30>=Assumptions!$B$7,3,"")))) -> 1 | O30: =IF(N30=1,Assumptions!$B$8,IF(N30=2,Assumptions!$B$9,IF(N30=3,Assumptions!$B$10,0))) -> 3 | P30: no data | Q30: no data | R30: no data | S30: no data | T30: no data | U30: no data | V30: no data | W30: no data | X30: no data | Y30: =IF(AND(X30="processed",ISNUMBER(S30)),S30*O30,"") | Z30: =IF(ISNUMBER(K30),K30*O30,0) -> 795 | AA30: INTERIM: Redfin SFR sales (12 mo) x tier weight | AB30: 19790 | AC30: 15146 | AD30: 1356 | AE30: 2118.6934 | AF30: 855.48492 | AG30: -0.029898979 | AH30: 1 | AI30: postal city of 100% of address points | AJ30: San Jose | AK30: San Jose
A31: 30 | B31: 94087 | C31: Sunnyvale | D31: Santa Clara | E31: Peninsula & South Bay (Santa Clara / San Mateo) | F31: Birdland | G31: San Jose, CA | H31: 1663.5655 | I31: SFR | J31: 2974583.3 | K31: 264 | M31: =TRUE() -> TRUE | N31: =IF(H31="","",IF(H31>=Assumptions!$B$5,1,IF(H31>=Assumptions!$B$6,2,IF(H31>=Assumptions!$B$7,3,"")))) -> 1 | O31: =IF(N31=1,Assumptions!$B$8,IF(N31=2,Assumptions!$B$9,IF(N31=3,Assumptions!$B$10,0))) -> 3 | P31: no data | Q31: no data | R31: no data | S31: no data | T31: no data | U31: no data | V31: no data | W31: no data | X31: no data | Y31: =IF(AND(X31="processed",ISNUMBER(S31)),S31*O31,"") | Z31: =IF(ISNUMBER(K31),K31*O31,0) -> 792 | AA31: INTERIM: Redfin SFR sales (12 mo) x tier weight | AB31: 16013 | AC31: 14159 | AD31: 352 | AE31: 2598.8044 | AF31: 1700.5137 | AG31: 0.003999641 | AH31: 1 | AI31: postal city of 100% of address points | AJ31: Sunnyvale | AK31: Sunnyvale
... A36: 35 | B36: 94110 | C36: San Francisco | D36: San Francisco | E36: San Francisco | F36: Mission; Bernal Heights | G36: San Francisco, CA | H36: 1088.6932 | I36: SFR | J36: 1544831.4 | K36: 258 | M36: =TRUE() -> TRUE | N36: =IF(H36="","",IF(H36>=Assumptions!$B$5,1,IF(H36>=Assumptions!$B$6,2,IF(H36>=Assumptions!$B$7,3,"")))) -> 1 | O36: =IF(N36=1,Assumptions!$B$8,IF(N36=2,Assumptions!$B$9,IF(N36=3,Assumptions!$B$10,0))) -> 3 | P36: no data | Q36: no data | R36: no data | S36: no data | T36: no data | U36: no data | V36: no data | W36: no data | X36: no data | Y36: =IF(AND(X36="processed",ISNUMBER(S36)),S36*O36,"") | Z36: =IF(ISNUMBER(K36),K36*O36,0) -> 774 | AA36: INTERIM: Redfin SFR sales (12 mo) x tier weight | AB36: 13215 | AC36: 12201 | AD36: 124 | AE36: 1283.7965 | AF36: 1270.6044 | AG36: 0.17144305 | AH36: 1 | AI36: postal city of 100% of address points | AJ36: San Francisco | AK36: San Francisco
A37: 36 | B37: 94611 | C37: Oakland | D37: Alameda | E37: Berkeley / Oakland / Alameda County | F37: Broadway Auto Row; Harrison/Oakland; Montclair; Oak Glen Park; Piedmont Avenue; Piedmont Pines; Westlake | G37: Oakland, CA | H37: 686.28151 | I37: SFR | J37: 1441336.8 | K37: 386 | M37: =TRUE() -> TRUE | N37: =IF(H37="","",IF(H37>=Assumptions!$B$5,1,IF(H37>=Assumptions!$B$6,2,IF(H37>=Assumptions!$B$7,3,"")))) -> 2 | O37: =IF(N37=1,Assumptions!$B$8,IF(N37=2,Assumptions!$B$9,IF(N37=3,Assumptions!$B$10,0))) -> 2 | P37: no data | Q37: no data | R37: no data | S37: no data | T37: no data | U37: no data | V37: no data | W37: no data | X37: no data | Y37: =IF(AND(X37="processed",ISNUMBER(S37)),S37*O37,"") | Z37: =IF(ISNUMBER(K37),K37*O37,0) -> 772 | AA37: INTERIM: Redfin SFR sales (12 mo) x tier weight | AB37: 14504 | AC37: 12003 | AD37: 222 | AE37: 1859.3853 | AF37: 746.78282 | AG37: 0.050811815 | AH37: 0.69565794 | AI37: locality polygon (largest overlap) | AK37: Oakland
A38: 37 | B38: 94560 | C38: Newark | D38: Alameda | E38: Berkeley / Oakland / Alameda County | G38: Oakland, CA | H38: 837.30364 | I38: SFR | J38: 1415045.1 | K38: 255 | M38: =TRUE() -> TRUE | N38: =IF(H38="","",IF(H38>=Assumptions!$B$5,1,IF(H38>=Assumptions!$B$6,2,IF(H38>=Assumptions!$B$7,3,"")))) -> 1 | O38: =IF(N38=1,Assumptions!$B$8,IF(N38=2,Assumptions!$B$9,IF(N38=3,Assumptions!$B$10,0))) -> 3 | P38: no data | Q38: no data | R38: no data | S38: no data | T38: no data | U38: no data | V38: no data | W38: no data | X38: no data | Y38: =IF(AND(X38="processed",ISNUMBER(S38)),S38*O38,"") | Z38: =IF(ISNUMBER(K38),K38*O38,0) -> 765 | AA38: INTERIM: Redfin SFR sales (12 mo) x tier weight | AB38: 13771 | AC38: 12732 | AD38: 379 | AE38: 2171.5312 | AF38: 860.50984 | AG38: -0.039838664 | AH38: 0.97684247 | AI38: locality polygon (largest overlap) | AK38: Newark
A39: 38 | B39: 92660 | C39: Newport Beach | D39: Orange | E39: Orange County | F39: UCI - North Campus; Bayside Village; Belcourt; Castaways; Granville; Harbor Cove; Harbor Hill; Harbor View Knoll; Island Lagoon; Newport Hills; Newport North; North Bluff; One Ford Road; Sea View; Seawind; The Bluffs; The Plaza; Villa Point; Big Canyon; Bonita Canyon; Dover Shores; Eastbluff; Harbor Island; Harbor Ridge; Harbor View; Newport Ridge; Upper Bay | G39: Anaheim, CA | H39: 1380.84 | I39: SFR | J39: 3893911.4 | K39: 254 | M39: =TRUE() -> TRUE | N39: =IF(H39="","",IF(H39>=Assumptions!$B$5,1,IF(H39>=Assumptions!$B$6,2,IF(H39>=Assumptions!$B$7,3,"")))) -> 1 | O39: =IF(N39=1,Assumptions!$B$8,IF(N39=2,Assumptions!$B$9,IF(N39=3,Assumptions!$B$10,0))) -> 3 | P39: no data | Q39: no data | R39: no data | S39: no data | T39: no data | U39: no data | V39: no data | W39: no data | X39: no data | Y39: =IF(AND(X39="processed",ISNUMBER(S39)),S39*O39,"") | Z39: =IF(ISNUMBER(K39),K39*O39,0) -> 762 | AA39: INTERIM: Redfin SFR sales (12 mo) x tier weight | AB39: 11926 | AC39: 10170 | AD39: 359 | AE39: 2954.4165 | AF39: 1478.8724 | AG39: 0.047389643 | AH39: 1 | AI39: postal city of 100% of address points | AJ39: Newport Beach | AK39: Newport Beach
A40: 39 | B40: 92127 | C40: San Diego | D40: San Diego | E40: San Diego | F40: Black Mountain Ranch; 4S Commons; Auberge; Bel Etage; Camino Bernardo; Deer Ridge; Dove Canyon; Ivygate; Nicole Ridge; Paseo Montenero; Stone Ranch; Tanner Ridge; Verrazano; Village Green; 4S Ranch Business Park; Del Sur; North 4S Ranch; Rancho Bernardo Business Park; Santaluz; South 4S Ranch; Westwood | G40: San Diego, CA | H40: 713.32127 | I40: SFR | J40: 2127369 | K40: 252 | M40: =TRUE() -> TRUE | N40: =IF(H40="","",IF(H40>=Assumptions!$B$5,1,IF(H40>=Assumptions!$B$6,2,IF(H40>=Assumptions!$B$7,3,"")))) -> 1 | O40: =IF(N40=1,Assumptions!$B$8,IF(N40=2,Assumptions!$B$9,IF(N40=3,Assumptions!$B$10,0))) -> 3 | P40: no data | Q40: no data | R40: no data | S40: no data | T40: no data | U40: no data | V40: no data | W40: no data | X40: no data | Y40: =IF(AND(X40="processed",ISNUMBER(S40)),S40*O40,"") | Z40: =IF(ISNUMBER(K40),K40*O40,0) -> 756 | AA40: INTERIM: Redfin SFR sales (12 mo) x tier weight | AB40: 14157 | AC40: 11513 | AD40: 471 | AE40: 2641.4402 | AF40: 728.29132 | AG40: -0.015384016 | AH40: 1 | AI40: postal city of 100% of address points | AJ40: San Diego | AK40: San Diego
A41: 40 | B41: 92064 | C41: Poway | D41: San Diego | E41: San Diego | F41: Bridlewood; Bridlewood Country Estates; Bridlewood Lakeside; Carriage Heights; Casa Real Poway; Cicero; Colony; Country Squire Estates; Cree; Espola Verde; Flair; Gate; Golden City; Green Valley Estates North; Green Valley Estates South; Green Valley Summit; Hickory; Holiday Estates; Holland; Huntington Gate; Kentfield; La Paz Village; Ladera Piedra; Las Cadenas; Midland Estates; Midland Grove; Norwalk; O'Reno; Padre Woods; Parkway Business Centre; Piermont; Pomerado Business Park; Pomerado Gardens; Poway Corporate Center; Poway Grove Park; Poway Mesa North; Poway Mesa South; Poway Portals; Poway Woods; Rancho Arbolitos Palisades; Rancho Arbolitos Parkside; Rancho Arbolitos Woodside; Rancho La Paz; Rancho Poway; Rancho Verde; Range View Estates; Rayo Del Sol; Rollin Glen; Stone Canyon Ranch; Stoneridge Chateaus; Summerfield Estates; Sunrise Ranch; Sycamore Creek; Taunt; Temple; The Grove; The Ranch; Twin Circle; Valle Del Norte; Valle Verde Estates; Avocado Glen; Green Valley; Old Coach; Old Poway; Poway Town Center; Rancho Arbolitos; South Poway Business Park; Twin Peaks | G41: San Diego, CA | H41: 641.68389 | I41: SFR | J41: 1304946.7 | K41: 375 | M41: =TRUE() -> TRUE | N41: =IF(H41="","",IF(H41>=Assumptions!$B$5,1,IF(H41>=Assumptions!$B$6,2,IF(H41>=Assumptions!$B$7,3,"")))) -> 2 | O41: =IF(N41=1,Assumptions!$B$8,IF(N41=2,Assumptions!$B$9,IF(N41=3,Assumptions!$B$10,0))) -> 2 | P41: no data | Q41: no data | R41: no data | S41: no data | T41: no data | U41: no data | V41: no data | W41: no data | X41: no data | Y41: =IF(AND(X41="processed",ISNUMBER(S41)),S41*O41,"") | Z41: =IF(ISNUMBER(K41),K41*O41,0) -> 750 | AA41: INTERIM: Redfin SFR sales (12 mo) x tier weight | AB41: 21277 | AC41: 15442 | AD41: 614 | AE41: 2588.7258 | AF41: 651.72591 | AG41: -0.03252838 | AH41: 1 | AI41: postal city of 100% of address points | AJ41: Poway | AK41: Poway
A42: 41 | B42: 92679 | C42: Rancho Santa Margarita | D42: Orange | E42: Orange County | F42: Dove Canyon; Portola Hills; Robinson Ranch | G42: Anaheim, CA | H42: 631.13114 | I42: SFR | J42: 1707626.7 | K42: 375 | M42: =TRUE() -> TRUE | N42: =IF(H42="","",IF(H42>=Assumptions!$B$5,1,IF(H42>=Assumptions!$B$6,2,IF(H42>=Assumptions!$B$7,3,"")))) -> 2 | O42: =IF(N42=1,Assumptions!$B$8,IF(N42=2,Assumptions!$B$9,IF(N42=3,Assumptions!$B$10,0))) -> 2 | P42: no data | Q42: no data | R42: no data | S42: no data | T42: no data | U42: no data | V42: no data | W42: no data | X42: no data | Y42: =IF(AND(X42="processed",ISNUMBER(S42)),S42*O42,"") | Z42: =IF(ISNUMBER(K42),K42*O42,0) -> 750 | AA42: INTERIM: Redfin SFR sales (12 mo) x tier weight | AB42: 10868 | AC42: 9921 | AD42: 125 | AE42: 2672.9153 | AF42: 637.39377 | AG42: -0.0042028514 | AH42: 1 | AI42: locality polygon (largest overlap) | AK42: Rancho Santa Margarita
A43: 42 | B43: 90068 | C43: Los Angeles | D43: Los Angeles | E43: Los Angeles County | F43: Beachwood Canyon; Hollywood Dell; Whitley Heights Historic District; Hollywood Hills | G43: Los Angeles, CA | H43: 870.9198 | I43: SFR | J43: 1959068.5 | K43: 248 | M43: =TRUE() -> TRUE | N43: =IF(H43="","",IF(H43>=Assumptions!$B$5,1,IF(H43>=Assumptions!$B$6,2,IF(H43>=Assumptions!$B$7,3,"")))) -> 1 | O43: =IF(N43=1,Assumptions!$B$8,IF(N43=2,Assumptions!$B$9,IF(N43=3,Assumptions!$B$10,0))) -> 3 | P43: no data | Q43: no data | R43: no data | S43: no data | T43: no data | U43: no data | V43: no data | W43: no data | X43: no data | Y43: =IF(AND(X43="processed",ISNUMBER(S43)),S43*O43,"") | Z43: =IF(ISNUMBER(K43),K43*O43,0) -> 744 | AA43: INTERIM: Redfin SFR sales (12 mo) x tier weight | AB43: 9105 | AC43: 7217 | AD43: 200 | AE43: 1975.3351 | AF43: 861.18252 | AG43: -0.082157766 | AH43: 1 | AI43: postal city of 100% of address points | AJ43: Los Angeles | AK43: Los Angeles
A44: 43 | B44: 95037 | C44: Morgan Hill | D44: Santa Clara | E44: Peninsula & South Bay (Santa Clara / San Mateo) | G44: San Jose, CA | H44: 660.69466 | I44: SFR | J44: 1471168 | K44: 372 | M44: =TRUE() -> TRUE | N44: =IF(H44="","",IF(H44>=Assumptions!$B$5,1,IF(H44>=Assumptions!$B$6,2,IF(H44>=Assumptions!$B$7,3,"")))) -> 2 | O44: =IF(N44=1,Assumptions!$B$8,IF(N44=2,Assumptions!$B$9,IF(N44=3,Assumptions!$B$10,0))) -> 2 | P44: no data | Q44: no data | R44: no data | S44: no data | T44: no data | U44: no data | V44: no data | W44: no data | X44: no data | Y44: =IF(AND(X44="processed",ISNUMBER(S44)),S44*O44,"") | Z44: =IF(ISNUMBER(K44),K44*O44,0) -> 744 | AA44: INTERIM: Redfin SFR sales (12 mo) x tier weight | AB44: 21407 | AC44: 17622 | AD44: 1801 | AE44: 2246.8826 | AF44: 673.07692 | AG44: 0.0045317221 | AH44: 0.99825094 | AI44: postal city of 100% of address points | AJ44: Morgan Hill | AK44: San Jose
...

Sheet By County
A1: Focus regions and every California county (live counts from 'All ZIPs')
A3: Region / county | B3: Counties | C3: ZIPs | D3: Tier 1 ZIPs | E3: Tier 2 ZIPs | F3: Tier 3 ZIPs | G3: Any-tier ZIPs | H3: SFR homes sold 12 mo (tiered ZIPs) | I3: Median of ZIP $/sq ft | J3: Parcel data status
A4: FOCUS REGIONS
A5: Orange County | B5: Orange | C5: =COUNTIF('All ZIPs'!$E$2:$E$1878,"Orange County") -> 88 | D5: =COUNTIFS('All ZIPs'!$E$2:$E$1878,"Orange County",'All ZIPs'!$N$2:$N$1878,1) -> 43 | E5: =COUNTIFS('All ZIPs'!$E$2:$E$1878,"Orange County",'All ZIPs'!$N$2:$N$1878,2) -> 40 | F5: =COUNTIFS('All ZIPs'!$E$2:$E$1878,"Orange County",'All ZIPs'!$N$2:$N$1878,3) -> 4 | G5: =SUM(D5:F5) -> 87 | H5: =SUMIFS('All ZIPs'!$K$2:$K$1878,'All ZIPs'!$E$2:$E$1878,"Orange County",'All ZIPs'!$N$2:$N$1878,">0") -> 13272 | I5: 699.61785 | J5: Orange: NO DATA ('portal' source needs a manual export to data/parcels/orange.gpkg)
A6: Los Angeles County | B6: Los Angeles | C6: =COUNTIF('All ZIPs'!$E$2:$E$1878,"Los Angeles County") -> 292 | D6: =COUNTIFS('All ZIPs'!$E$2:$E$1878,"Los Angeles County",'All ZIPs'!$N$2:$N$1878,1) -> 104 | E6: =COUNTIFS('All ZIPs'!$E$2:$E$1878,"Los Angeles County",'All ZIPs'!$N$2:$N$1878,2) -> 60 | F6: =COUNTIFS('All ZIPs'!$E$2:$E$1878,"Los Angeles County",'All ZIPs'!$N$2:$N$1878,3) -> 85 | G6: =SUM(D6:F6) -> 249 | H6: =SUMIFS('All ZIPs'!$K$2:$K$1878,'All ZIPs'!$E$2:$E$1878,"Los Angeles County",'All ZIPs'!$N$2:$N$1878,">0") -> 29492 | I6: 630.83209 | J6: Los Angeles: NO DATA (BLOCKED by this environment's network policy (proxy 403))
A7: San Francisco | B7: San Francisco | C7: =COUNTIF('All ZIPs'!$E$2:$E$1878,"San Francisco") -> 27 | D7: =COUNTIFS('All ZIPs'!$E$2:$E$1878,"San Francisco",'All ZIPs'!$N$2:$N$1878,1) -> 25 | E7: =COUNTIFS('All ZIPs'!$E$2:$E$1878,"San Francisco",'All ZIPs'!$N$2:$N$1878,2) -> 1 | F7: =COUNTIFS('All ZIPs'!$E$2:$E$1878,"San Francisco",'All ZIPs'!$N$2:$N$1878,3) -> 0 | G7: =SUM(D7:F7) -> 26 | H7: =SUMIFS('All ZIPs'!$K$2:$K$1878,'All ZIPs'!$E$2:$E$1878,"San Francisco",'All ZIPs'!$N$2:$N$1878,">0") -> 2990 | I7: 1095.5127 | J7: San Francisco: NO DATA ('portal' source needs a manual export to data/parcels/san_francisco.gpkg)
A8: Berkeley / Oakland / Alameda County | B8: Alameda | C8: =COUNTIF('All ZIPs'!$E$2:$E$1878,"Berkeley / Oakland / Alameda County") -> 49 | D8: =COUNTIFS('All ZIPs'!$E$2:$E$1878,"Berkeley / Oakland / Alameda County",'All ZIPs'!$N$2:$N$1878,1) -> 24 | E8: =COUNTIFS('All ZIPs'!$E$2:$E$1878,"Berkeley / Oakland / Alameda County",'All ZIPs'!$N$2:$N$1878,2) -> 14 | F8: =COUNTIFS('All ZIPs'!$E$2:$E$1878,"Berkeley / Oakland / Alameda County",'All ZIPs'!$N$2:$N$1878,3) -> 2 | G8: =SUM(D8:F8) -> 40 | H8: =SUMIFS('All ZIPs'!$K$2:$K$1878,'All ZIPs'!$E$2:$E$1878,"Berkeley / Oakland / Alameda County",'All ZIPs'!$N$2:$N$1878,">0") -> 6865 | I8: 704.67241 | J8: Alameda: NO DATA ('portal' source needs a manual export to data/parcels/alameda.gpkg)
A9: Peninsula & South Bay (Santa Clara / San Mateo) | B9: Santa Clara, San Mateo | C9: =COUNTIF('All ZIPs'!$E$2:$E$1878,"Peninsula & South Bay (Santa Clara / San Mateo)") -> 87 | D9: =COUNTIFS('All ZIPs'!$E$2:$E$1878,"Peninsula & South Bay (Santa Clara / San Mateo)",'All ZIPs'!$N$2:$N$1878,1) -> 77 | E9: =COUNTIFS('All ZIPs'!$E$2:$E$1878,"Peninsula & South Bay (Santa Clara / San Mateo)",'All ZIPs'!$N$2:$N$1878,2) -> 2 | F9: =COUNTIFS('All ZIPs'!$E$2:$E$1878,"Peninsula & South Bay (Santa Clara / San Mateo)",'All ZIPs'!$N$2:$N$1878,3) -> 2 | G9: =SUM(D9:F9) -> 81 | H9: =SUMIFS('All ZIPs'!$K$2:$K$1878,'All ZIPs'!$E$2:$E$1878,"Peninsula & South Bay (Santa Clara / San Mateo)",'All ZIPs'!$N$2:$N$1878,">0") -> 11827 | I9: 1102.9571 | J9: Santa Clara: NO DATA ('portal' source needs a manual export to data/parcels/santa_clara.gpkg); San Mateo: NO DATA ('portal' source needs a manual export to data/parcels/san_mateo.gpkg)
A10: Marin | B10: Marin | C10: =COUNTIF('All ZIPs'!$E$2:$E$1878,"Marin") -> 29 | D10: =COUNTIFS('All ZIPs'!$E$2:$E$1878,"Marin",'All ZIPs'!$N$2:$N$1878,1) -> 20 | E10: =COUNTIFS('All ZIPs'!$E$2:$E$1878,"Marin",'All ZIPs'!$N$2:$N$1878,2) -> 4 | F10: =COUNTIFS('All ZIPs'!$E$2:$E$1878,"Marin",'All ZIPs'!$N$2:$N$1878,3) -> 2 | G10: =SUM(D10:F10) -> 26 | H10: =SUMIFS('All ZIPs'!$K$2:$K$1878,'All ZIPs'!$E$2:$E$1878,"Marin",'All ZIPs'!$N$2:$N$1878,">0") -> 1881 | I10: 880.84278 | J10: Marin: NO DATA ('portal' source needs a manual export to data/parcels/marin.gpkg)
A11: San Diego | B11: San Diego | C11: =COUNTIF('All ZIPs'!$E$2:$E$1878,"San Diego") -> 106 | D11: =COUNTIFS('All ZIPs'!$E$2:$E$1878,"San Diego",'All ZIPs'!$N$2:$N$1878,1) -> 31 | E11: =COUNTIFS('All ZIPs'!$E$2:$E$1878,"San Diego",'All ZIPs'!$N$2:$N$1878,2) -> 12 | F11: =COUNTIFS('All ZIPs'!$E$2:$E$1878,"San Diego",'All ZIPs'!$N$2:$N$1878,3) -> 26 | G11: =SUM(D11:F11) -> 69 | H11: =SUMIFS('All ZIPs'!$K$2:$K$1878,'All ZIPs'!$E$2:$E$1878,"San Diego",'All ZIPs'!$N$2:$N$1878,">0") -> 11468 | I11: 558.32242 | J11: San Diego: NO DATA (BLOCKED by this environment's network policy (proxy 403))
A12: Ventura | B12: Ventura | C12: =COUNTIF('All ZIPs'!$E$2:$E$1878,"Ventura") -> 29 | D12: =COUNTIFS('All ZIPs'!$E$2:$E$1878,"Ventura",'All ZIPs'!$N$2:$N$1878,1) -> 4 | E12: =COUNTIFS('All ZIPs'!$E$2:$E$1878,"Ventura",'All ZIPs'!$N$2:$N$1878,2) -> 2 | F12: =COUNTIFS('All ZIPs'!$E$2:$E$1878,"Ventura",'All ZIPs'!$N$2:$N$1878,3) -> 9 | G12: =SUM(D12:F12) -> 15 | H12: =SUMIFS('All ZIPs'!$K$2:$K$1878,'All ZIPs'!$E$2:$E$1878,"Ventura",'All ZIPs'!$N$2:$N$1878,">0") -> 2910 | I12: 510.59736 | J12: Ventura: NO DATA ('portal' source needs a manual export to data/parcels/ventura.gpkg)
A13: Sacramento | B13: Sacramento | C13: =COUNTIF('All ZIPs'!$E$2:$E$1878,"Sacramento") -> 54 | D13: =COUNTIFS('All ZIPs'!$E$2:$E$1878,"Sacramento",'All ZIPs'!$N$2:$N$1878,1) -> 0 | E13: =COUNTIFS('All ZIPs'!$E$2:$E$1878,"Sacramento",'All ZIPs'!$N$2:$N$1878,2) -> 0 | F13: =COUNTIFS('All ZIPs'!$E$2:$E$1878,"Sacramento",'All ZIPs'!$N$2:$N$1878,3) -> 3 | G13: =SUM(D13:F13) -> 3 | H13: =SUMIFS('All ZIPs'!$K$2:$K$1878,'All ZIPs'!$E$2:$E$1878,"Sacramento",'All ZIPs'!$N$2:$N$1878,">0") -> 494 | I13: 336.10695 | J13: Sacramento: NO DATA ('portal' source needs a manual export to data/parcels/sacramento.gpkg)
